<mujoco model="MOZ1">
  <!-- Spirit01 STL meshes live at `tools/rl_sim/meshes/`. The meshdir below
       is resolved relative to this XML, so keep the meshes directory next
       to moz1_pd.xml; loaders that patch meshdir (e.g. rl_juggle_env_random)
       will also default to that same location. -->
  <compiler angle="radian" meshdir="meshes/"/>
  <option timestep="0.001" integrator="implicitfast" iterations="100"/>

  <default>
    <joint damping="2.0" armature="0.02"/>
  </default>

  <asset>
    <mesh name="base_link" content_type="model/stl" file="base_link.STL"/>
    <mesh name="wheel" content_type="model/stl" file="wheel.STL"/>
    <mesh name="leg01" content_type="model/stl" file="leg01.STL"/>
    <mesh name="leg02" content_type="model/stl" file="leg02.STL"/>
    <mesh name="leg03" content_type="model/stl" file="leg03.STL"/>
    <mesh name="waist01" content_type="model/stl" file="waist01.STL"/>
    <mesh name="waist02" content_type="model/stl" file="waist02.STL"/>
    <mesh name="waist03" content_type="model/stl" file="waist03.STL"/>
    <mesh name="left01" content_type="model/stl" file="left01.STL"/>
    <mesh name="left02" content_type="model/stl" file="left02.STL"/>
    <mesh name="left03" content_type="model/stl" file="left03.STL"/>
    <mesh name="left04" content_type="model/stl" file="left04.STL"/>
    <mesh name="left05" content_type="model/stl" file="left05.STL"/>
    <mesh name="left06" content_type="model/stl" file="left06.STL"/>
    <mesh name="left07" content_type="model/stl" file="left07.STL"/>
    <mesh name="right01" content_type="model/stl" file="right01.STL"/>
    <mesh name="right02" content_type="model/stl" file="right02.STL"/>
    <mesh name="right03" content_type="model/stl" file="right03.STL"/>
    <mesh name="right04" content_type="model/stl" file="right04.STL"/>
    <mesh name="right05" content_type="model/stl" file="right05.STL"/>
    <mesh name="right06" content_type="model/stl" file="right06.STL"/>
    <mesh name="right07" content_type="model/stl" file="right07.STL"/>
    <mesh name="head21" content_type="model/stl" file="head21.STL"/>
    <mesh name="head22" content_type="model/stl" file="head22.STL"/>
    <mesh name="head23" content_type="model/stl" file="head23.STL"/>
  </asset>

  <worldbody>
    <body name="base" pos="0 0 0.1" >
        <!-- 底盘 6-DOF：x / y / z / roll / pitch / yaw -->
        <joint name="base_x" type="slide" axis="1 0 0" range="-3 3"/>
        <joint name="base_y" type="slide" axis="0 1 0" range="-3 3"/>
        <joint name="base_z" type="slide" axis="0 0 1" range="-1 2"/>
        <joint name="base_roll" type="hinge" axis="1 0 0" range="-3.14159 3.14159"/>
        <joint name="base_pitch" type="hinge" axis="0 1 0" range="-3.14159 3.14159"/>
        <joint name="base_yaw" type="hinge" axis="0 0 1" range="-3.14159 3.14159"/>
        <!-- 显式定义 base 惯性（参考 URDF 的 base_link 参数） -->
        <inertial
          pos="0.00718 0.03634 0.03333"
          mass="120.64"
          fullinertia="1.86830738 1.63486351 2.82299198 -0.05906676 0.02042256 0.0809264"/>
        <geom type="mesh" contype="0" conaffinity="0" group="1" density="0" rgba="0.8 0.8 0.8 1" mesh="base_link"/>
        <geom type="mesh" contype="1" conaffinity="1" rgba="0.8 0.8 0.8 1" mesh="base_link"/>
        <geom size="0.05 0.05 0.05" pos="0 -0.2522 0.1919" type="box" contype="0" conaffinity="0" group="1" density="0" rgba="0.3 0.3 0.3 1"/>
        <geom size="0.05 0.05 0.05" pos="0 -0.2522 0.1919" type="box" contype="1" conaffinity="1" rgba="0.3 0.3 0.3 1"/>
        <body name="wheel01" pos="0.2423 0.2423 0" quat="0.382683 0 0 0.92388">
        <inertial pos="-2.82895e-08 3.64072e-08 0.00740011" quat="0.595864 0.380721 -0.595858 0.380724" mass="2.71499" diaginertia="0.00157803 0.00100847 0.00100846"/>
        <geom type="mesh" contype="0" conaffinity="0" group="1" density="0" rgba="0.8 0.8 0.8 1" mesh="wheel"/>
        <geom type="mesh" contype="1" conaffinity="1" rgba="0.8 0.8 0.8 1" mesh="wheel"/>
        </body>
        <body name="wheel02" pos="-0.2423 0.2423 0" quat="0.382683 0 0 -0.92388">
        <inertial pos="-2.82895e-08 3.64072e-08 0.00740011" quat="0.595864 0.380721 -0.595858 0.380724" mass="2.71499" diaginertia="0.00157803 0.00100847 0.00100846"/>
        <geom type="mesh" contype="0" conaffinity="0" group="1" density="0" rgba="0.8 0.8 0.8 1" mesh="wheel"/>
        <geom type="mesh" contype="1" conaffinity="1" rgba="0.8 0.8 0.8 1" mesh="wheel"/>
        </body>
        <body name="wheel03" pos="-0.2423 -0.2423 0" quat="0.92388 0 0 -0.382683">
        <inertial pos="-2.82895e-08 3.64072e-08 0.00740011" quat="0.595864 0.380721 -0.595858 0.380724" mass="2.71499" diaginertia="0.00157803 0.00100847 0.00100846"/>
        <geom type="mesh" contype="0" conaffinity="0" group="1" density="0" rgba="0.8 0.8 0.8 1" mesh="wheel"/>
        <geom type="mesh" contype="1" conaffinity="1" rgba="0.8 0.8 0.8 1" mesh="wheel"/>
        </body>
        <body name="wheel04" pos="0.2423 -0.2423 0" quat="0.92388 0 0 0.382683">
        <inertial pos="-2.82895e-08 3.64072e-08 0.00740011" quat="0.595864 0.380721 -0.595858 0.380724" mass="2.71499" diaginertia="0.00157803 0.00100847 0.00100846"/>
        <geom type="mesh" contype="0" conaffinity="0" group="1" density="0" rgba="0.8 0.8 0.8 1" mesh="wheel"/>
        <geom type="mesh" contype="1" conaffinity="1" rgba="0.8 0.8 0.8 1" mesh="wheel"/>
        </body>
        <body name="leg01" pos="0 0.1114 0.1875">
        <inertial pos="-0.00617037 -0.00163202 0.0684463" quat="0.962802 -6.77789e-05 0.0441614 -0.266575" mass="5.0191" diaginertia="0.0282473 0.0280715 0.00910457"/>
        <joint name="LegWaist-0" pos="0 0 0" axis="0 1 0" range="-0.523599 0.523599"/>
        <geom type="mesh" contype="0" conaffinity="0" group="1" density="0" rgba="0.8 0.8 0.8 1" mesh="leg01"/>
        <geom type="mesh" rgba="0.8 0.8 0.8 1" mesh="leg01"/>
        <body name="leg02" pos="0 0 0.122">
            <inertial pos="-0.00881747 -0.00241472 0.16018" quat="0.70294 0.000989748 0.00607775 0.711222" mass="5.93199" diaginertia="0.10396 0.0892351 0.0275517"/>
            <joint name="LegWaist-1" pos="0 0 0" axis="1 0 0" range="-1.5708 1.5708"/>
            <geom type="mesh" contype="0" conaffinity="0" group="1" density="0" rgba="0.8 0.8 0.8 1" mesh="leg02"/>
            <geom type="mesh" rgba="0.8 0.8 0.8 1" mesh="leg02"/>
            <body name="leg03" pos="0 0 0.285">
            <inertial pos="-0.009383 -0.00063508 0.169736" quat="0.705122 0.0154655 0.0158399 0.708741" mass="6.15147" diaginertia="0.141413 0.131774 0.0240241"/>
            <joint name="LegWaist-2" pos="0 0 0" axis="1 0 0" range="-2.53073 0.0174533"/>
            <geom type="mesh" contype="0" conaffinity="0" group="1" density="0" rgba="0.8 0.8 0.8 1" mesh="leg03"/>
            <geom type="mesh" rgba="0.8 0.8 0.8 1" mesh="leg03"/>
            <body name="waist01" pos="0 0 0.318">
                <inertial pos="-0.00217777 0.0057512 0.0681478" quat="0.970866 0.0340474 -0.0270485 0.235645" mass="5.02421" diaginertia="0.0290882 0.0287938 0.0102116"/>
                <joint name="LegWaist-3" pos="0 0 0" axis="1 0 0" range="-0.174533 1.39626"/>
                <geom type="mesh" contype="0" conaffinity="0" group="1" density="0" rgba="0.8 0.8 0.8 1" mesh="waist01"/>
                <geom type="mesh" rgba="0.8 0.8 0.8 1" mesh="waist01"/>
                <body name="waist02" pos="0 0 0.12">
                <inertial pos="0 0.0093749 0.0713126" quat="0.9863 -0.164959 1.96397e-05 0.000666705" mass="3.22037" diaginertia="0.0216605 0.0174409 0.00984487"/>
                <joint name="LegWaist-4" pos="0 0 0" axis="0 1 0" range="-0.523599 0.523599"/>
                <geom type="mesh" contype="0" conaffinity="0" group="1" density="0" rgba="0.89804 0.91765 0.92941 1" mesh="waist02"/>
                <geom type="mesh" rgba="0.89804 0.91765 0.92941 1" mesh="waist02"/>
                <body name="waist03" pos="0 0 0.355">
                    <inertial pos="0.00888336 0.00326024 0.166819" quat="0.71133 0.00521061 -0.00281674 0.702834" mass="10.8638" diaginertia="0.107903 0.0778723 0.0572099"/>
                    <joint name="LegWaist-5" pos="0 0 0" axis="0 0 1" range="-3.14159 3.14159"/>
                    <geom pos="0 0 -0.2531" quat="1 0 0 0" type="mesh" contype="0" conaffinity="0" group="1" density="0" rgba="0.8 0.8 0.8 1" mesh="waist03"/>
                    <geom pos="0 0 -0.2531" quat="1 0 0 0" type="mesh" rgba="0.8 0.8 0.8 1" mesh="waist03"/>
                    <body name="left01" pos="0.1257 0 0">
                    <inertial pos="0.0547495 0.00276998 0.00022292" quat="0.513235 0.51481 0.485909 0.485235" mass="2.26362" diaginertia="0.00609871 0.00593897 0.00291596"/>
                    <joint name="LeftArm-0" pos="0 0 0" axis="1 0 0" range="-3.14159 2.0944"/>
                    <geom type="mesh" contype="0" conaffinity="0" group="1" density="0" rgba="0.8 0.8 0.8 1" mesh="left01"/>
                    <geom type="mesh" rgba="0.8 0.8 0.8 1" mesh="left01"/>
                    <body name="left02" pos="0.079 0 0">
                        <inertial pos="-0.0007589 -0.00895001 -0.0590928" quat="0.995435 -0.0936704 -0.0118428 -0.0139783" mass="1.70151" diaginertia="0.00997199 0.00848993 0.00349083"/>
                        <joint name="LeftArm-1" pos="0 0 0" axis="0 1 0" range="-2.96706 0.15708"/>
                        <geom type="mesh" contype="0" conaffinity="0" group="1" density="0" rgba="0.8 0.8 0.8 1" mesh="left02"/>
                        <geom type="mesh" rgba="0.8 0.8 0.8 1" mesh="left02"/>
                        <body name="left03" pos="0 0 -0.113">
                        <inertial pos="0.00354184 0.00051786 -0.122916" quat="0.682881 0.0238508 0.0228831 0.729781" mass="2.16229" diaginertia="0.0125343 0.0123931 0.00259313"/>
                        <joint name="LeftArm-2" pos="0 0 0" axis="0 0 1" range="-3.05433 3.05433"/>
                        <geom type="mesh" contype="0" conaffinity="0" group="1" density="0" rgba="0.8 0.8 0.8 1" mesh="left03"/>
                        <geom type="mesh" rgba="0.8 0.8 0.8 1" mesh="left03"/>
                        <body name="left04" pos="0 0 -0.187">
                            <inertial pos="-0.0173898 7.621e-05 -0.0568789" quat="0.992135 -0.000332296 0.125109 -0.00396338" mass="1.06371" diaginertia="0.00459925 0.00451648 0.000796607"/>
                            <joint name="LeftArm-3" pos="0 0 0" axis="1 0 0" range="-2.25147 0.174533"/>
                            <geom type="mesh" contype="0" conaffinity="0" group="1" density="0" rgba="0.8 0.8 0.8 1" mesh="left04"/>
                            <geom type="mesh" rgba="0.8 0.8 0.8 1" mesh="left04"/>
                            <body name="left05" pos="0 0 -0.101">
                            <inertial pos="0.00156708 -0.00511158 -0.0988337" quat="0.822469 0.0226677 -0.0436238 0.566681" mass="1.62899" diaginertia="0.00748142 0.00738898 0.00174301"/>
                            <joint name="LeftArm-4" pos="0 0 0" axis="0 0 1" range="-3.05433 3.05433"/>
                            <geom type="mesh" contype="0" conaffinity="0" group="1" density="0" rgba="0.8 0.8 0.8 1" mesh="left05"/>
                            <geom type="mesh" rgba="0.8 0.8 0.8 1" mesh="left05"/>
                            <body name="left06" pos="0 0 -0.159">
                                <inertial pos="0.0116648 0.0105348 -0.0501291" quat="0.427373 0.142559 -0.0530785 0.891186" mass="0.92138" diaginertia="0.00292962 0.00248792 0.000689094"/>
                                <joint name="LeftArm-5" pos="0 0 0" axis="0 1 0" range="-1.65806 1.65806"/>
                                <geom type="mesh" contype="0" conaffinity="0" group="1" density="0" rgba="0.8 0.8 0.8 1" mesh="left06"/>
                                <geom type="mesh" rgba="0.8 0.8 0.8 1" mesh="left06"/>
                                <body name="left07" pos="0 0 -0.0905">
                                <inertial pos="-0.0050797 -3.643e-05 -0.00136032" quat="0.999385 0.000256411 -0.0318119 0.0147291" mass="0.688226" diaginertia="0.00073418 0.000715242 0.000680363"/>
                                <joint name="LeftArm-6" pos="0 0 0" axis="1 0 0" range="-1.5708 1.5708"/>
                                <geom type="mesh" contype="0" conaffinity="0" group="1" density="0" rgba="0.8 0.8 0.8 1" mesh="left07"/>
                                <geom type="mesh" rgba="0.8 0.8 0.8 1" mesh="left07"/>
                                <!-- 球形末端(可接触)；EE 采样点设置在球心 -->
                                </body>
                            </body>
                            </body>
                        </body>
                        </body>
                    </body>
                    </body>
                    <body name="right01" pos="-0.1257 0 0" quat="0 0 0 1">
                    <inertial pos="0.0547406 0.00275389 0.00021783" quat="0.512414 0.515656 0.485013 0.4861" mass="2.26441" diaginertia="0.00610134 0.00594309 0.0029178"/>
                    <joint name="RightArm-0" pos="0 0 0" axis="1 0 0" range="-2.0944 3.14159"/>
                    <geom pos="0 0 0" quat="0 0 0 -1" type="mesh" contype="0" conaffinity="0" group="1" density="0" rgba="0.8 0.8 0.8 1" mesh="right01"/>
                    <geom pos="0 0 0" quat="0 0 0 -1" type="mesh" rgba="0.8 0.8 0.8 1" mesh="right01"/>
                    <body name="right02" pos="0.079 0 0">
                        <inertial pos="-0.00080565 -0.00894661 -0.0591091" quat="0.995388 -0.0939747 -0.0122957 -0.0148393" mass="1.703" diaginertia="0.00997889 0.00849501 0.00349393"/>
                        <joint name="RightArm-1" pos="0 0 0" axis="0 1 0" range="-2.96706 0.15708"/>
                        <geom quat="0 0 0 -1" type="mesh" contype="0" conaffinity="0" group="1" density="0" rgba="0.8 0.8 0.8 1" mesh="right02"/>
                        <geom quat="0 0 0 -1" type="mesh" rgba="0.8 0.8 0.8 1" mesh="right02"/>
                        <body name="right03" pos="0 0 -0.113">
                        <inertial pos="0.00357305 -0.000532 -0.122917" quat="0.727073 0.0228923 0.0234807 0.685776" mass="2.16234" diaginertia="0.0125339 0.0123926 0.00259347"/>
                        <joint name="RightArm-2" pos="0 0 0" axis="0 0 1" range="-3.05433 3.05433"/>
                        <geom pos="0 0 0" quat="0 0 0 -1" type="mesh" contype="0" conaffinity="0" group="1" density="0" rgba="0.8 0.8 0.8 1" mesh="right03"/>
                        <geom pos="0 0 0" quat="0 0 0 -1" type="mesh" rgba="0.8 0.8 0.8 1" mesh="right03"/>
                        <body name="right04" pos="0 0 -0.187">
                            <inertial pos="-0.0174054 6.063e-05 -0.0568789" quat="0.992133 -0.000584718 0.12502 -0.00653609" mass="1.06371" diaginertia="0.00459893 0.0045159 0.000796365"/>
                            <joint name="RightArm-3" pos="0 0 0" axis="1 0 0" range="-0.174533 2.25147"/>
                            <geom quat="0 0 0 -1" type="mesh" contype="0" conaffinity="0" group="1" density="0" rgba="0.8 0.8 0.8 1" mesh="right04"/>
                            <geom quat="0 0 0 -1" type="mesh" rgba="0.8 0.8 0.8 1" mesh="right04"/>
                            <body name="right05" pos="0 0 -0.101">
                            <inertial pos="0.00161137 0.00511103 -0.0988326" quat="0.573299 -0.0436085 0.0224213 0.817877" mass="1.62901" diaginertia="0.00748005 0.00739018 0.00174314"/>
                            <joint name="RightArm-4" pos="0 0 0" axis="0 0 1" range="-3.05433 3.05433"/>
                            <geom pos="0 0 0" quat="0 0 0 -1" type="mesh" contype="0" conaffinity="0" group="1" density="0" rgba="0.8 0.8 0.8 1" mesh="right05"/>
                            <geom pos="0 0 0" quat="0 0 0 -1" type="mesh" rgba="0.8 0.8 0.8 1" mesh="right05"/>
                            <body name="right06" pos="0 0 -0.159">
                                <inertial pos="0.0116071 -0.0105291 -0.0501088" quat="0.891286 -0.0531369 0.142593 0.427145" mass="0.920443" diaginertia="0.00292821 0.00248449 0.000688387"/>
                                <joint name="RightArm-5" pos="0 0 0" axis="0 1 0" range="-1.65806 1.65806"/>
                                <geom quat="0 0 0 -1" type="mesh" contype="0" conaffinity="0" group="1" density="0" rgba="0.8 0.8 0.8 1" mesh="right06"/>
                                <geom quat="0 0 0 -1" type="mesh" rgba="0.8 0.8 0.8 1" mesh="right06"/>
                                <body name="right07" pos="0 0 -0.0905">
                                <inertial pos="-0.00513252 -4.962e-05 -0.0013123" quat="0.999469 0.000593911 -0.0199028 0.0257912" mass="0.689154" diaginertia="0.000735483 0.000717832 0.00068216"/>
                                <joint name="RightArm-6" pos="0 0 0" axis="1 0 0" range="-1.5708 1.5708"/>
                                <geom quat="0 0 0 -1" type="mesh" contype="0" conaffinity="0" group="1" density="0" rgba="0.8 0.8 0.8 1" mesh="right07"/>
                                <geom quat="0 0 0 -1" type="mesh" rgba="0.8 0.8 0.8 1" mesh="right07"/>
                                  <!-- 末端球拍：参考 ball_model/ball.xml 的两层圆拍 -->
                                  <body name="right_racket" pos="0 0 -0.215" quat="0.7 0 0.7 0">
                                  <geom name="racket_wood" type="cylinder" size="0.08 0.005" rgba="0.5 0.2 0.1 1" contype="0" conaffinity="0"/>
                                  <geom name="racket_rubber_fore" type="cylinder" size="0.08 0.002" pos="0 0 0.007"
                                    rgba="0.8 0.1 0.1 1" solref="0.003 0.80" solimp="0.90 0.995 0.001" friction="0.35 0.002 0.0001" margin="0.001" condim="3" contype="1" conaffinity="1"/>

                                  <!-- 末端参考点 -->
                                  <site name="right_ee_site" pos="0 0 0.007" size="0.004" rgba="0 0 0 0"/>
                                  </body>
                                  </body>
                            </body>
                            </body>
                        </body>
                        </body>
                    </body>
                    </body>
                    <body name="head21" pos="0 0 0.096">
                    <inertial pos="-0.00245506 0.010184 0.00271658" quat="0.878008 0.0733771 0.26317 0.393014" mass="0.568364" diaginertia="0.000250158 0.000206895 0.000142512"/>
                    <joint name="Head-0" pos="0 0 0" axis="0 0 1" range="-1.5708 1.5708"/>
                    <geom type="mesh" contype="0" conaffinity="0" group="1" density="0" rgba="0.8 0.8 0.8 1" mesh="head21"/>
                    <geom type="mesh" rgba="0.8 0.8 0.8 1" mesh="head21"/>
                    <body name="head22" pos="0 0 0.103">
                        <inertial pos="0.0247462 2.03517e-06 0.0172814" quat="0.654409 0.284667 0.293336 0.636135" mass="1.11591" diaginertia="0.000897947 0.000884832 0.000296763"/>
                        <joint name="Head-1" pos="0 0 0" axis="1 0 0" range="-1.5708 1.5708"/>
                        <geom type="mesh" contype="0" conaffinity="0" group="1" density="0" rgba="0.8 0.8 0.8 1" mesh="head22"/>
                        <geom type="mesh" rgba="0.8 0.8 0.8 1" mesh="head22"/>
                        <geom pos="0 0 0.04" type="mesh" contype="0" conaffinity="0" group="1" density="0" rgba="0.8 0.8 0.8 1" mesh="head23"/>
                        <geom pos="0 0 0.04" type="mesh" rgba="0.8 0.8 0.8 1" mesh="head23"/>
                    </body>
                    </body>
                </body>
                </body>
            </body>
            </body>
        </body>
        </body>
    </body>

    <geom name="floor" pos="0 0 0" size="0 0 0.01" type="plane" material="groundplane" contype="1" conaffinity="0" priority="1"
      friction="0.6" condim="3"/>

    <!-- 机器人前方墙体（沿 y 方向展开） -->
    <geom
      name="front_wall"
      type="box"
      pos="1.2 0 0.75"
      size="0.05 1.0 0.75"
      rgba="0.75 0.75 0.78 1"
      contype="1"
      conaffinity="1"
      friction="0.8 0.1 0.1"/>

    <light diffuse=".5 .5 .5" pos="-3 -3 5" dir="3 3 -5" castshadow="true"/>
  </worldbody>
  <asset>
    <texture type="skybox" builtin="gradient" rgb1="1 1 1" rgb2="1 1 1" width="800" height="800"/>
    <texture type="2d" name="groundplane" builtin="checker" mark="edge" rgb1="1 1 1" rgb2="1 1 1" markrgb="0 0 0"
      width="300" height="300"/>
    <material name="groundplane" texture="groundplane" texuniform="true" texrepeat="5 5" reflectance="0"/>
    <texture type="skybox" builtin="gradient" rgb1=".4 .5 .6" rgb2="0 0 0" width="100" height="100"/>
    <texture builtin="flat" height="1278" mark="cross" markrgb="1 1 1" name="texgeom" random="0.01" rgb1="0.8 0.6 0.4" rgb2="0.8 0.6 0.4" type="cube" width="127"/>
    <texture name="texplane" builtin="checker" height="512" width="512" rgb1=".2 .3 .4" rgb2=".1 .15 .2" type="2d" />
    <material name="MatPlane" reflectance="0.5" shininess="0.01" specular="0.1" texrepeat="1 1" texture="texplane" texuniform="true" />
    <material name="geom" texture="texgeom" texuniform="true"/>
  </asset>

<!-- ...existing code... -->
  <actuator>
    <!-- 底盘：x / y / yaw 速度控制 -->
    <velocity name="Base-X" joint="base_x" ctrlrange="-1.5 1.5" ctrllimited="true" kv="2500" gear="1" forcelimited="true" forcerange="-2000000 2000000"/>
    <velocity name="Base-Y" joint="base_y" ctrlrange="-1.5 1.5" ctrllimited="true" kv="2500" gear="1" forcelimited="true" forcerange="-2000000 2000000"/>
    <velocity name="Base-Yaw" joint="base_yaw" ctrlrange="-2.5 2.5" ctrllimited="true" kv="1500" gear="1" forcelimited="true" forcerange="-1500000 1500000"/>

    <!-- 腿+腰：位置控制（ctrlrange 对齐 joint range） -->
    <position name="LegWaist-0" joint="LegWaist-0" ctrlrange="-0.523599 0.523599" ctrllimited="true" kp="80000" kv="8000"/>
    <position name="LegWaist-1" joint="LegWaist-1" ctrlrange="-1.5708 1.5708"   ctrllimited="true" kp="50000" kv="3000"/>
    <position name="LegWaist-2" joint="LegWaist-2" ctrlrange="-2.53073 0.0174533" ctrllimited="true" kp="20000" kv="1000"/>
    <position name="LegWaist-3" joint="LegWaist-3" ctrlrange="-0.174533 1.39626"  ctrllimited="true" kp="90000" kv="2500"/>
    <position name="LegWaist-4" joint="LegWaist-4" ctrlrange="-0.523599 0.523599" ctrllimited="true" kp="100000" kv="8000"/>
    <position name="LegWaist-5" joint="LegWaist-5" ctrlrange="-3.14159 3.14159"   ctrllimited="true" kp="80000" kv="7000"/>
    <!-- 左臂 -->
    <position name="LeftArm-0" joint="LeftArm-0" ctrlrange="-3.14159 2.0944"  ctrllimited="true" kp="6500" kv="330"/>
    <position name="LeftArm-1" joint="LeftArm-1" ctrlrange="-2.96706 0.15708"  ctrllimited="true" kp="6500" kv="200"/>
    <position name="LeftArm-2" joint="LeftArm-2" ctrlrange="-3.05433 3.05433"  ctrllimited="true" kp="6000" kv="200"/>
    <position name="LeftArm-3" joint="LeftArm-3" ctrlrange="-2.25147 0.174533" ctrllimited="true" kp="1000" kv="30"/>
    <position name="LeftArm-4" joint="LeftArm-4" ctrlrange="-3.05433 3.05433"  ctrllimited="true" kp="300" kv="6"/>
    <position name="LeftArm-5" joint="LeftArm-5" ctrlrange="-1.65806 1.65806"  ctrllimited="true" kp="4000" kv="50"/>
    <position name="LeftArm-6" joint="LeftArm-6" ctrlrange="-1.5708 1.5708"    ctrllimited="true" kp="600" kv="6"/>

    <!-- 右臂：提高刚度/阻尼，优先改善球拍末端跟踪 -->
    <position name="RightArm-0" joint="RightArm-0" ctrlrange="-2.0944 3.14159"  ctrllimited="true" kp="32000" kv="2000"/>
    <position name="RightArm-1" joint="RightArm-1" ctrlrange="-2.96706 0.15708"  ctrllimited="true" kp="32000" kv="1800"/>
    <position name="RightArm-2" joint="RightArm-2" ctrlrange="-3.05433 3.05433"  ctrllimited="true" kp="27000" kv="1500"/>
    <position name="RightArm-3" joint="RightArm-3" ctrlrange="-0.174533 2.25147" ctrllimited="true" kp="20000" kv="900"/>
    <position name="RightArm-4" joint="RightArm-4" ctrlrange="-3.05433 3.05433"  ctrllimited="true" kp="13000" kv="500"/>
    <position name="RightArm-5" joint="RightArm-5" ctrlrange="-1.65806 1.65806"  ctrllimited="true" kp="15000" kv="500"/>
    <position name="RightArm-6" joint="RightArm-6" ctrlrange="-1.5708 1.5708"    ctrllimited="true" kp="10000" kv="350"/>

    <!-- 头部 -->
    <position name="Head-0" joint="Head-0" ctrlrange="-1.5708 1.5708" ctrllimited="true" kp="40" kv="4"/>
    <position name="Head-1" joint="Head-1" ctrlrange="-1.5708 1.5708" ctrllimited="true" kp="40" kv="4"/>
  </actuator>

  <sensor>
    <!-- 底盘位置传感器 -->
    <jointpos name="base_x_pos" joint="base_x"/>
    <jointpos name="base_y_pos" joint="base_y"/>
    <jointpos name="base_yaw_pos" joint="base_yaw"/>

    <!-- 底盘速度传感器 -->
    <jointvel name="base_x_vel" joint="base_x"/>
    <jointvel name="base_y_vel" joint="base_y"/>
    <jointvel name="base_yaw_vel" joint="base_yaw"/>
  </sensor>
<!-- ...existing code... -->
</mujoco>
